<?xml version="1.0" encoding="utf-8"?>
<!-- This URDF was automatically created by SolidWorks to URDF Exporter! Originally created by Stephen Brawner (brawner@gmail.com) 
     Commit Version: 1.6.0-1-g15f4949  Build Version: 1.6.7594.29634
     For more information, please see http://wiki.ros.org/sw_urdf_exporter -->
<robot
  name="rtabmap_drone_example">
  <link
    name="base_link">
    <inertial>
      <origin
        xyz="0.00034936 -1.2569E-16 0.074871"
        rpy="0 0 0" />
      <mass
        value="1.7812" />
      <inertia
        ixx="0.039416"
        ixy="8.0246E-17"
        ixz="-6.4933E-06"
        iyy="0.052638"
        iyz="1.0456E-17"
        izz="0.078952" />
    </inertial>
    <visual>
      <origin
        xyz="0 0 0.5"
        rpy="0 0 0" />
      <geometry>
        <mesh
          filename="package://rtabmap_drone_example/meshes/base_link.STL" />
      </geometry>
      <material
        name="">
        <color
          rgba="0.79216 0.81961 0.93333 1" />
      </material>
    </visual>
    <collision>
      <origin
        xyz="0 0 0.5"
        rpy="0 0 0" />
      <geometry>
        <mesh
          filename="package://rtabmap_drone_example/meshes/base_link.STL" />
      </geometry>
    </collision>
  </link>
  <link
    name="Right Leg">
    <inertial>
      <origin
        xyz="0.00038782 0.010897 -0.12262"
        rpy="0 0 0" />
      <mass
        value="0.31991" />
      <inertia
        ixx="0.002218"
        ixy="6.0311E-07"
        ixz="-1.5213E-05"
        iyy="0.0089633"
        iyz="-0.0001907"
        izz="0.0070283" />
    </inertial>
    <visual>
      <origin
        xyz="0 0 0.5"
        rpy="0 0 0" />
      <geometry>
        <mesh
          filename="package://rtabmap_drone_example/meshes/Right Leg.STL" />
      </geometry>
      <material
        name="">
        <color
          rgba="0.79216 0.81961 0.93333 1" />
      </material>
    </visual>
    <collision>
      <origin
        xyz="0 0 0.5"
        rpy="0 0 0" />
      <geometry>
        <mesh
          filename="package://rtabmap_drone_example/meshes/Right Leg.STL" />
      </geometry>
    </collision>
  </link>
  <joint
    name="Right Leg Rotation joint"
    type="continuous">
    <origin
      xyz="0.01821 -0.195 0.05"
      rpy="0 0 0" />
    <parent
      link="base_link" />
    <child
      link="Right Leg" />
    <axis
      xyz="0 1 0" />
    <limit
      lower="-1"
      upper="1"
      effort="0.1"
      velocity="5" />
    <dynamics
      damping="0.1"
      friction="0.3" />
  </joint>
  <link
    name="Right Bevel Gear">
    <inertial>
      <origin
        xyz="1.0674E-06 0.011527 -0.00015591"
        rpy="0 0 0" />
      <mass
        value="0.0057917" />
      <inertia
        ixx="4.3602E-07"
        ixy="9.433E-12"
        ixz="-3.5834E-11"
        iyy="4.6745E-07"
        iyz="-1.3781E-09"
        izz="4.4125E-07" />
    </inertial>
    <visual>
      <origin
        xyz="0 0 0.5"
        rpy="0 0 0" />
      <geometry>
        <mesh
          filename="package://rtabmap_drone_example/meshes/Right Bevel Gear.STL" />
      </geometry>
      <material
        name="">
        <color
          rgba="0.77647 0.75686 0.73725 1" />
      </material>
    </visual>
    <collision>
      <origin
        xyz="0 0 0.5"
        rpy="0 0 0" />
      <geometry>
        <mesh
          filename="package://rtabmap_drone_example/meshes/Right Bevel Gear.STL" />
      </geometry>
    </collision>
  </link>
  <joint
    name="Right Bevel Gear Rotation Joint"
    type="fixed">
    <origin
      xyz="0 0.163 0"
      rpy="0 0 0" />
    <parent
      link="Right Leg" />
    <child
      link="Right Bevel Gear" />
    <axis
      xyz="0 0 0" />
    <limit
      effort="0.1"
      velocity="5" />
    <dynamics
      damping="0.1"
      friction="0.1" />
  </joint>
  <link
    name="BRW">
    <inertial>
      <origin
        xyz="-5.4229E-13 3.0256E-13 0.015"
        rpy="0 0 0" />
      <mass
        value="1.0141" />
      <inertia
        ixx="0.0051773"
        ixy="3.4742E-18"
        ixz="1.1045E-20"
        iyy="0.0051773"
        iyz="-1.1331E-19"
        izz="0.0091744" />
    </inertial>
    <visual>
      <origin
        xyz="0 0 0.5"
        rpy="0 0 0" />
      <geometry>
        <mesh
          filename="package://rtabmap_drone_example/meshes/BRW.STL" />
      </geometry>
      <material
        name="">
        <color
          rgba="0.79216 0.81961 0.93333 1" />
      </material>
    </visual>
    <collision>
      <origin
        xyz="0 0 0.5"
        rpy="0 0 0" />
      <geometry>
        <mesh
          filename="package://rtabmap_drone_example/meshes/BRW.STL" />
      </geometry>
    </collision>
  </link>
  <joint
    name="BRW Joint"
    type="continuous">
    <origin
      xyz="-0.2467 -0.05 -0.24827"
      rpy="1.5708 0 0" />
    <parent
      link="Right Leg" />
    <child
      link="BRW" />
    <axis
      xyz="0 0 1" />
    <limit
      effort="0.1"
      velocity="0" />
    <dynamics
      damping="0.1"
      friction="0.1" />
  </joint>
  <link
    name="FRW">
    <inertial>
      <origin
        xyz="-5.4232E-13 -0.015 3.0256E-13"
        rpy="0 0 0" />
      <mass
        value="1.0141" />
      <inertia
        ixx="0.0051773"
        ixy="-7.4206E-20"
        ixz="2.1103E-18"
        iyy="0.0091744"
        iyz="1.105E-19"
        izz="0.0051773" />
    </inertial>
    <visual>
      <origin
        xyz="0 0 0.5"
        rpy="0 0 0" />
      <geometry>
        <mesh
          filename="package://rtabmap_drone_example/meshes/FRW.STL" />
      </geometry>
      <material
        name="">
        <color
          rgba="0.79216 0.81961 0.93333 1" />
      </material>
    </visual>
    <collision>
      <origin
        xyz="0 0 0.5"
        rpy="0 0 0" />
      <geometry>
        <mesh
          filename="package://rtabmap_drone_example/meshes/FRW.STL" />
      </geometry>
    </collision>
  </link>
  <joint
    name="FRW Joint"
    type="continuous">
    <origin
      xyz="0.24827 -0.05 -0.2467"
      rpy="0 0 0" />
    <parent
      link="Right Leg" />
    <child
      link="FRW" />
    <axis
      xyz="0 -1 0" />
    <limit
      effort="0.1"
      velocity="0" />
    <dynamics
      damping="0.1"
      friction="0.1" />
  </joint>
  <link
    name="Left Leg">
    <inertial>
      <origin
        xyz="-0.0010767 -0.010897 -0.12262"
        rpy="0 0 0" />
      <mass
        value="0.31991" />
      <inertia
        ixx="0.0022183"
        ixy="1.6745E-06"
        ixz="4.2237E-05"
        iyy="0.0089633"
        iyz="0.00019069"
        izz="0.0070279" />
    </inertial>
    <visual>
      <origin
        xyz="0 0 0.5"
        rpy="0 0 0" />
      <geometry>
        <mesh
          filename="package://rtabmap_drone_example/meshes/Left Leg.STL" />
      </geometry>
      <material
        name="">
        <color
          rgba="0.79216 0.81961 0.93333 1" />
      </material>
    </visual>
    <collision>
      <origin
        xyz="0 0 0.5"
        rpy="0 0 0" />
      <geometry>
        <mesh
          filename="package://rtabmap_drone_example/meshes/Left Leg.STL" />
      </geometry>
    </collision>
  </link>
  <joint
    name="Left Leg Rotation Joint"
    type="continuous">
    <origin
      xyz="0.01821 0.195 0.05"
      rpy="0 0 0" />
    <parent
      link="base_link" />
    <child
      link="Left Leg" />
    <axis
      xyz="0 -1 0" />
    <limit
      lower="-1"
      upper="1"
      effort="0.1"
      velocity="5" />
    <dynamics
      damping="0.1"
      friction="0.3" />
  </joint>
  <link
    name="Left Bevel Gear">
    <inertial>
      <origin
        xyz="-1.8831E-06 -0.011527 -0.00015591"
        rpy="0 0 0" />
      <mass
        value="0.0057917" />
      <inertia
        ixx="4.3602E-07"
        ixy="1.6643E-11"
        ixz="6.3216E-11"
        iyy="4.6745E-07"
        iyz="1.378E-09"
        izz="4.4125E-07" />
    </inertial>
    <visual>
      <origin
        xyz="0 0 0.5"
        rpy="0 0 0" />
      <geometry>
        <mesh
          filename="package://rtabmap_drone_example/meshes/Left Bevel Gear.STL" />
      </geometry>
      <material
        name="">
        <color
          rgba="0.77647 0.75686 0.73725 1" />
      </material>
    </visual>
    <collision>
      <origin
        xyz="0 0 0.5"
        rpy="0 0 0" />
      <geometry>
        <mesh
          filename="package://rtabmap_drone_example/meshes/Left Bevel Gear.STL" />
      </geometry>
    </collision>
  </link>
  <joint
    name="Left Bevel Gear Rotation Joint"
    type="fixed">
    <origin
      xyz="0 -0.163 0"
      rpy="0 0 0" />
    <parent
      link="Left Leg" />
    <child
      link="Left Bevel Gear" />
    <axis
      xyz="0 0 0" />
    <limit
      effort="0.1"
      velocity="5" />
    <dynamics
      damping="0.1"
      friction="0.1" />
  </joint>
  <link
    name="BLW">
    <inertial>
      <origin
        xyz="-5.4237E-13 0.015 3.0256E-13"
        rpy="0 0 0" />
      <mass
        value="1.0141" />
      <inertia
        ixx="0.0051773"
        ixy="-5.0537E-20"
        ixz="2.0784E-18"
        iyy="0.0091744"
        iyz="7.1288E-20"
        izz="0.0051773" />
    </inertial>
    <visual>
      <origin
        xyz="0 0 0"
        rpy="0 0 0" />
      <geometry>
        <mesh
          filename="package://rtabmap_drone_example/meshes/BLW.STL" />
      </geometry>
      <material
        name="">
        <color
          rgba="0.79216 0.81961 0.93333 1" />
      </material>
    </visual>
    <collision>
      <origin
        xyz="0 0 0.5"
        rpy="0 0 0" />
      <geometry>
        <mesh
          filename="package://rtabmap_drone_example/meshes/BLW.STL" />
      </geometry>
    </collision>
  </link>
  <joint
    name="BLW joint"
    type="continuous">
    <origin
      xyz="-0.24965 0.05 -0.2453"
      rpy="0 0 0" />
    <parent
      link="Left Leg" />
    <child
      link="BLW" />
    <axis
      xyz="0 1 0" />
    <limit
      effort="0.1"
      velocity="0" />
    <dynamics
      damping="0.1"
      friction="0.1" />
  </joint>
  <link
    name="FLW">
    <inertial>
      <origin
        xyz="-5.4232E-13 0.015 3.0259E-13"
        rpy="0 0 0" />
      <mass
        value="1.0141" />
      <inertia
        ixx="0.0051773"
        ixy="-3.8947E-20"
        ixz="2.3404E-18"
        iyy="0.0091744"
        iyz="8.1892E-20"
        izz="0.0051773" />
    </inertial>
    <visual>
      <origin
        xyz="0 0 0.5"
        rpy="0 0 0" />
      <geometry>
        <mesh
          filename="package://rtabmap_drone_example/meshes/FLW.STL" />
      </geometry>
      <material
        name="">
        <color
          rgba="0.79216 0.81961 0.93333 1" />
      </material>
    </visual>
    <collision>
      <origin
        xyz="0 0 0"
        rpy="0 0 0" />
      <geometry>
        <mesh
          filename="package://rtabmap_drone_example/meshes/FLW.STL" />
      </geometry>
    </collision>
  </link>
  <joint
    name="FLW joint"
    type="continuous">
    <origin
      xyz="0.2453 0.05 -0.24965"
      rpy="0 0 0" />
    <parent
      link="Left Leg" />
    <child
      link="FLW" />
    <axis
      xyz="0 1 0" />
    <limit
      effort="0.1"
      velocity="0" />
    <dynamics
      damping="0.1"
      friction="0.1" />
  </joint>
  <link
    name="Center Bevel Gear">
    <inertial>
      <origin
        xyz="0 0 0"
        rpy="0 0 0" />
      <mass
        value="0" />
      <inertia
        ixx="0"
        ixy="0"
        ixz="0"
        iyy="0"
        iyz="0"
        izz="0" />
    </inertial>
    <visual>
      <origin
        xyz="0 0 0.5"
        rpy="0 0 0" />
      <geometry>
        <mesh
          filename="package://rtabmap_drone_example/meshes/Center Bevel Gear.STL" />
      </geometry>
      <material
        name="">
        <color
          rgba="1 1 1 1" />
      </material>
    </visual>
    <collision>
      <origin
        xyz="0 0 0.5"
        rpy="0 0 0" />
      <geometry>
        <mesh
          filename="package://rtabmap_drone_example/meshes/Center Bevel Gear.STL" />
      </geometry>
    </collision>
  </link>
  <joint
    name="Center Bevel Gear Rotation Joint"
    type="continuous">
    <origin
      xyz="-0.01399 0 0.05"
      rpy="0 0 0" />
    <parent
      link="base_link" />
    <child
      link="Center Bevel Gear" />
    <axis
      xyz="1 0 0" />
    <limit
      effort="0.1"
      velocity="5" />
    <dynamics
      damping="0.1"
      friction="0.1" />
  </joint>
</robot>
